When `catch` block throws new exception, and the previous exception is lost.
